Workbook

Sheet Cover
A1: INFOSYS LIMITED Business Valuation — DCF Analysis FY2022–FY2031
B11: Valuation Date: | E11: 31 March 2026
B12: Methodology: | E12: Discounted Cash Flow (FCFF)
B13: Historical Period: | E13: FY2022 – FY2026
B14: Forecast Period: | E14: FY2027 – FY2031
B15: Currency: | E15: INR (₹) in Crores (Cr)
B16: Exchange Rate: | E16: 1 USD = 83.5 INR (approx.)
B17: Stock Exchange: | E17: NSE / BSE | Ticker: INFY
B18: Prepared By: | E18: Valuation Analyst – Transaction Advisory
B19: Model Version: | E19: v1.0 | Analyst-Grade DCF
B22: DISCLAIMER: This model is prepared for educational and internship-portfolio purposes only. All data sourced from Infosys Annual Reports & NSE filings. This does not constitute investment advice.
B28: # | C28: Sheet | E28: Description
B29: 1 | C29: Cover | E29: Project overview and navigation
B30: 2 | C30: Historical Financials | E30: IS / BS / CFS – FY2022 to FY2026
B31: 3 | C31: Assumptions | E31: All driver assumptions with rationale
B32: 4 | C32: Forecast Model | E32: 5-year projected financials
B33: 5 | C33: DCF Valuation | E33: EV, Equity Value, Intrinsic Price
B34: 6 | C34: Sensitivity Analysis | E34: WACC vs TGR matrix
B35: 7 | C35: Dashboard | E35: Visual summary of key outputs

Sheet Historical Financials
A1: INFOSYS LIMITED — Historical Financial Statements (FY2022–FY2026)
A2: All figures in INR Crores (₹ Cr) | Source: Infosys Annual Reports, NSE Filings
A4: INCOME STATEMENT
A5: Particulars (₹ Cr) | D5: FY2022 | E5: FY2023 | F5: FY2024 | G5: FY2025 | H5: FY2026
A6: Revenue from Operations | D6: 121641 | E6: 146767 | F6: 153670 | G6: 165809 | H6: 180143
A7: YoY Revenue Growth % | D7: N/A | E7: =(E6-D6)/D6 -> 0.20655864 | F7: =(F6-E6)/E6 -> 0.047033734 | G7: =(G6-F6)/F6 -> 0.078993948 | H7: =(H6-G6)/G6 -> 0.086448866
A8: Cost of Sales | D8: 77726 | E8: 92989 | F8: 97680 | G8: 104984 | H8: 114432
A9: Gross Profit | D9: =D6-D8 -> 43915 | E9: =E6-E8 -> 53778 | F9: =F6-F8 -> 55990 | G9: =G6-G8 -> 60825 | H9: =H6-H8 -> 65711
A10: Gross Margin % | D10: =D9/D6 -> 0.36102137 | E10: =E9/E6 -> 0.36641752 | F10: =F9/F6 -> 0.36435218 | G10: =G9/G6 -> 0.36683775 | H10: =H9/H6 -> 0.36477132
A11: SG&A / Other Expenses | D11: 18936 | E11: 21812 | F11: 22450 | G11: 24190 | H11: 27021
A12: EBITDA | D12: =D9-D11 -> 24979 | E12: =E9-E11 -> 31966 | F12: =F9-F11 -> 33540 | G12: =G9-G11 -> 36635 | H12: =H9-H11 -> 38690
A13: EBITDA Margin % | D13: =D12/D6 -> 0.20535017 | E13: =E12/E6 -> 0.217801 | F13: =F12/F6 -> 0.21825991 | G13: =G12/G6 -> 0.22094699 | H13: =H12/H6 -> 0.21477382
A14: Depreciation & Amortisation | D14: 4917 | E14: 5407 | F14: 5851 | G14: 6229 | H14: 6737
A15: EBIT | D15: =D12-D14 -> 20062 | E15: =E12-E14 -> 26559 | F15: =F12-F14 -> 27689 | G15: =G12-G14 -> 30406 | H15: =H12-H14 -> 31953
A16: EBIT Margin % | D16: =D15/D6 -> 0.16492794 | E16: =E15/E6 -> 0.1809603 | F16: =F15/F6 -> 0.18018481 | G16: =G15/G6 -> 0.18337967 | H16: =H15/H6 -> 0.17737575
A17: Other Income (Net) | D17: 2701 | E17: 3128 | F17: 3404 | G17: 3890 | H17: 4215
A18: PBT | D18: =D15+D17 -> 22763 | E18: =E15+E17 -> 29687 | F18: =F15+F17 -> 31093 | G18: =G15+G17 -> 34296 | H18: =H15+H17 -> 36168
A19: Tax Expense | D19: 6334 | E19: 7626 | F19: 7985 | G19: 8611 | H19: 9408
A20: Effective Tax Rate % | D20: =IF(D18=0,0,D19/D18) -> 0.27825858 | E20: =IF(E18=0,0,E19/E18) -> 0.25688012 | F20: =IF(F18=0,0,F19/F18) -> 0.25681021 | G20: =IF(G18=0,0,G19/G18) -> 0.25107884 | H20: =IF(H18=0,0,H19/H18) -> 0.26011944
A21: PAT (Net Income) | D21: =D18-D19 -> 16429 | E21: =E18-E19 -> 22061 | F21: =F18-F19 -> 23108 | G21: =G18-G19 -> 25685 | H21: =H18-H19 -> 26760
A22: PAT Margin % | D22: =D21/D6 -> 0.13506137 | E22: =E21/E6 -> 0.15031308 | F22: =F21/F6 -> 0.15037418 | G22: =G21/G6 -> 0.15490715 | H22: =H21/H6 -> 0.14854865
A23: NOPAT (EBIT×(1-t)) | D23: =D15*(1-D20) -> 14479.576 | E23: =E15*(1-E20) -> 19736.521 | F23: =F15*(1-F20) -> 20578.182 | G23: =G15*(1-G20) -> 22771.697 | H23: =H15*(1-H20) -> 23641.403
A26: BALANCE SHEET (SELECTED ITEMS)
A27: Particulars (₹ Cr) | D27: FY2022 | E27: FY2023 | F27: FY2024 | G27: FY2025 | H27: FY2026
A28: Cash & Cash Equivalents | D28: 16278 | E28: 14721 | F28: 13839 | G28: 14298 | H28: 15450
A29: Trade Receivables | D29: 18203 | E29: 21876 | F29: 22451 | G29: 23904 | H29: 25897
A30: Other Current Assets | D30: 12403 | E30: 14221 | F30: 15110 | G30: 16342 | H30: 17821
A31: Total Current Assets | D31: =D28+D29+D30 -> 46884 | E31: =E28+E29+E30 -> 50818 | F31: =F28+F29+F30 -> 51400 | G31: =G28+G29+G30 -> 54544 | H31: =H28+H29+H30 -> 59168
A32: Trade Payables | D32: 4312 | E32: 5102 | F32: 5389 | G32: 5921 | H32: 6432
A33: Other Current Liabilities | D33: 14823 | E33: 17432 | F33: 18241 | G33: 19832 | H33: 21455
A34: Total Current Liabilities | D34: =D32+D33 -> 19135 | E34: =E32+E33 -> 22534 | F34: =F32+F33 -> 23630 | G34: =G32+G33 -> 25753 | H34: =H32+H33 -> 27887
A35: Net Working Capital | D35: =D31-D34-D28 -> 11471 | E35: =E31-E34-E28 -> 13563 | F35: =F31-F34-F28 -> 13931 | G35: =G31-G34-G28 -> 14493 | H35: =H31-H34-H28 -> 15831
A36: NWC as % of Revenue | D36: =D35/D6 -> 0.094302086 | E36: =E35/E6 -> 0.092411782 | F36: =F35/F6 -> 0.0906553 | G36: =G35/G6 -> 0.087407801 | H36: =H35/H6 -> 0.087880184
A37: Fixed Assets (Net Block) | D37: 19823 | E37: 21042 | F37: 22134 | G37: 23187 | H37: 24102
A38: Total Debt | D38: 3421 | E38: 3218 | F38: 4102 | G38: 3984 | H38: 3741
A39: Total Equity | D39: 71462 | E39: 76821 | F39: 79034 | G39: 82341 | H39: 86742
A42: CASH FLOW STATEMENT (SELECTED ITEMS)
A43: Particulars (₹ Cr) | D43: FY2022 | E43: FY2023 | F43: FY2024 | G43: FY2025 | H43: FY2026
A44: CFO – Operating Cash Flow | D44: 25842 | E44: 28734 | F44: 30102 | G44: 32145 | H44: 34892
A45: Capex (Purchase of Fixed Assets) | D45: 5834 | E45: 6102 | F45: 6241 | G45: 6832 | H45: 7124
...

Sheet Assumptions
A1: INFOSYS DCF — KEY ASSUMPTIONS & RATIONALE
A3: REVENUE GROWTH ASSUMPTIONS
A4: Driver | B4: Metric | D4: FY2027 | E4: FY2028 | F4: FY2029 | G4: FY2030 | H4: FY2031 | I4: Source | J4: Rationale
A5: Revenue Growth % | B5: % YoY | D5: 0.1 | E5: 0.095 | F5: 0.09 | G5: 0.085 | H5: 0.08 | I5: Infosys AR / Consensus — moderated from ~14% CAGR to reflect base effect
A7: PROFITABILITY ASSUMPTIONS
A8: Driver | B8: Metric | D8: FY2027 | E8: FY2028 | F8: FY2029 | G8: FY2030 | H8: FY2031 | I8: Source | J8: Rationale
A9: EBIT Margin % | B9: % of Rev | D9: 0.23 | E9: 0.232 | F9: 0.234 | G9: 0.236 | H9: 0.238
A10: Effective Tax Rate % | B10: % of Rev | D10: 0.261 | E10: 0.261 | F10: 0.261 | G10: 0.261 | H10: 0.261
A11: D&A as % of Revenue | B11: % of Rev | D11: 0.038 | E11: 0.037 | F11: 0.037 | G11: 0.036 | H11: 0.036
A12: Capex as % of Revenue | B12: % of Rev | D12: 0.04 | E12: 0.039 | F12: 0.038 | G12: 0.037 | H12: 0.036
A13: NWC as % of Revenue | B13: % of Rev | D13: 0.075 | E13: 0.075 | F13: 0.074 | G13: 0.074 | H13: 0.073
A15: WACC INPUTS
A16: Parameter | B16: Basis | C16: Value | D16: Formula / Note
A17: Risk-Free Rate (Rf) | B17: 10Y GoI Bond Yield | C17: 0.071 | D17: 10Y GoI Bond Yield
A18: Equity Risk Premium (ERP) | B18: Damodaran India ERP | C18: 0.078 | D18: Damodaran India ERP
A19: Beta (β) | B19: NSE 2Y Adjusted Beta | C19: 0.85 | D19: NSE 2Y Adjusted Beta
A20: Cost of Equity (Ke) | B20: CAPM: Rf + β×ERP | C20: =C17+C19*C18 -> 0.1373 | D20: Rf + Beta x ERP (CAPM)
A21: Pre-tax Cost of Debt (Kd) | B21: Marginal Borrowing Rate | C21: 0.082 | D21: Marginal Borrowing Rate
A22: Tax Rate (for Kd shield) | B22: Effective Rate | C22: 0.261 | D22: Effective Rate
A23: After-tax Kd | B23: Kd×(1-t) | C23: =C21*(1-C22) -> 0.060598 | D23: Kd x (1 - Tax Rate)
A24: Market Cap (₹ Cr) | B24: NSE Market Cap ~Apr 2026 | C24: 614200 | D24: NSE Market Cap ~Apr 2026
A25: Total Debt (₹ Cr) | B25: From Balance Sheet | C25: 3741 | D25: From Balance Sheet
A26: Equity Weight (We) | B26: E/(E+D) | C26: =C24/(C24+C25) -> 0.99394602 | D26: E / (E + D)
A27: Debt Weight (Wd) | B27: D/(E+D) | C27: =C25/(C24+C25) -> 0.006053976 | D27: D / (E + D)
A28: WACC | B28: We×Ke + Wd×Kd(1-t) | C28: =C26*C20+C27*C23 -> 0.13683565 | D28: We x Ke + Wd x Kd(1-t)
A29: Terminal Growth Rate (g) | B29: LT GDP + Inflation proxy | C29: 0.055 | D29: LT GDP + Inflation proxy

Sheet Forecast Model
A1: INFOSYS LIMITED — 5-Year Forecast Model (FY2027–FY2031)
A2: All figures in INR Crores (₹ Cr) | Assumptions sourced from 'Assumptions' tab | Blue = input | Black = formula | Green = cross-sheet link
A4: Particulars (₹ Cr) | D4: FY2027 | E4: FY2028 | F4: FY2029 | G4: FY2030 | H4: FY2031
A5: FORECASTED INCOME STATEMENT
A6: Revenue from Operations | D6: ='Historical Financials'!H6*(1+Assumptions!D5) -> 198157.3 | E6: =D6*(1+Assumptions!E5) -> 216982.24 | F6: =E6*(1+Assumptions!F5) -> 236510.65 | G6: =F6*(1+Assumptions!G5) -> 256614.05 | H6: =G6*(1+Assumptions!H5) -> 277143.17
A7: YoY Revenue Growth % | D7: =Assumptions!D5 -> 0.1 | E7: =Assumptions!E5 -> 0.095 | F7: =Assumptions!F5 -> 0.09 | G7: =Assumptions!G5 -> 0.085 | H7: =Assumptions!H5 -> 0.08
A8: EBIT | D8: =D6*Assumptions!D9 -> 45576.179 | E8: =E6*Assumptions!E9 -> 50339.88 | F8: =F6*Assumptions!F9 -> 55343.491 | G8: =G6*Assumptions!G9 -> 60560.916 | H8: =H6*Assumptions!H9 -> 65960.075
A9: EBIT Margin % | D9: =Assumptions!D9 -> 0.23 | E9: =Assumptions!E9 -> 0.232 | F9: =Assumptions!F9 -> 0.234 | G9: =Assumptions!G9 -> 0.236 | H9: =Assumptions!H9 -> 0.238
A10: Tax Expense | D10: =D7*D9 -> 0.023 | E10: =E7*E9 -> 0.02204 | F10: =F7*F9 -> 0.02106 | G10: =G7*G9 -> 0.02006 | H10: =H7*H9 -> 0.01904
A11: Effective Tax Rate % | D11: =Assumptions!D10 -> 0.261 | E11: =Assumptions!E10 -> 0.261 | F11: =Assumptions!F10 -> 0.261 | G11: =Assumptions!G10 -> 0.261 | H11: =Assumptions!H10 -> 0.261
A12: NOPAT | D12: =D8*(1-D11) -> 33680.796 | E12: =E8*(1-E11) -> 37201.172 | F12: =F8*(1-F11) -> 40898.84 | G12: =G8*(1-G11) -> 44754.517 | H12: =H8*(1-H11) -> 48744.496
A13: Depreciation & Amortisation | D13: =D6*Assumptions!D11 -> 7529.9774 | E13: =E6*Assumptions!E11 -> 8028.343 | F13: =F6*Assumptions!F11 -> 8750.8939 | G13: =G6*Assumptions!G11 -> 9238.1058 | H13: =H6*Assumptions!H11 -> 9977.1543
A14: Capex | D14: =D6*Assumptions!D12 -> 7926.292 | E14: =E6*Assumptions!E12 -> 8462.3075 | F14: =F6*Assumptions!F12 -> 8987.4045 | G14: =G6*Assumptions!G12 -> 9494.7199 | H14: =H6*Assumptions!H12 -> 9977.1543
A15: Change in Net Working Capital | D15: =(D6*Assumptions!D13)-'Historical Financials'!H35 -> -969.2025 | E15: =(E6*Assumptions!E13)-(D6*Assumptions!D13) -> 1411.8708 | F15: =(F6*Assumptions!F13)-(E6*Assumptions!E13) -> 1228.1195 | G15: =(G6*Assumptions!G13)-(F6*Assumptions!F13) -> 1487.652 | H15: =(H6*Assumptions!H13)-(G6*Assumptions!G13) -> 1242.012
A16: FCFF | D16: =D12+D13-D14-D15 -> 34253.684 | E16: =E12+E13-E14-E15 -> 35355.336 | F16: =F12+F13-F14-F15 -> 39434.21 | G16: =G12+G13-G14-G15 -> 43010.251 | H16: =H12+H13-H14-H15 -> 47502.484
A18: FCFF Formula: NOPAT + D&A – Capex – ΔNWC | NOPAT = EBIT × (1 – Tax Rate) | All assumptions linked from 'Assumptions' tab

Sheet DCF Valuation
A1: INFOSYS LIMITED — DCF VALUATION (FCFF Method)
A3: STEP 1: FREE CASH FLOW TO FIRM (FCFF)
A4: Particulars (₹ Cr) | C4: FY2027 | D4: FY2028 | E4: FY2029 | F4: FY2030 | G4: FY2031
A5: FCFF (₹ Cr) | C5: ='Forecast Model'!D16 -> 34253.684 | D5: ='Forecast Model'!E16 -> 35355.336 | E5: ='Forecast Model'!F16 -> 39434.21 | F5: ='Forecast Model'!G16 -> 43010.251 | G5: ='Forecast Model'!H16 -> 47502.484
A6: Discount Period (n) | C6: 1 | D6: 2 | E6: 3 | F6: 4 | G6: 5
A7: Discount Factor | C7: =1/(1+Assumptions!C28)^C6 -> 0.87963463 | D7: =1/(1+Assumptions!C28)^D6 -> 0.77375708 | E7: =1/(1+Assumptions!C28)^E6 -> 0.68062352 | F7: =1/(1+Assumptions!C28)^F6 -> 0.59870001 | G7: =1/(1+Assumptions!C28)^G6 -> 0.52663726
A8: PV of FCFF | C8: =C5*C7 -> 30130.727 | D8: =D5*D7 -> 27356.442 | E8: =E5*E7 -> 26839.85 | F8: =F5*F7 -> 25750.238 | G8: =G5*G7 -> 25016.578
A10: Sum of PV of FCFF (₹ Cr) | C10: =SUM(C8:G8) -> 135093.83
A12: STEP 2: TERMINAL VALUE (Gordon Growth Model)
A13: FCFF in Terminal Year (FY2031, ₹ Cr) | C13: ='Forecast Model'!H16 -> 47502.484
A14: Terminal Growth Rate (g) | C14: =Assumptions!C29 -> 0.055
A15: WACC | C15: =Assumptions!C28 -> 0.13683565
A16: Terminal Value (₹ Cr) | C16: =(C13*(1+C14))/(C15-C14) -> 612387.41
A17: PV of Terminal Value (₹ Cr) | C17: =C16/(1+Assumptions!C28)^5 -> 322506.03
A18: TV as % of Enterprise Value | C18: =C17/(C10+C17) -> 0.70477737
A20: STEP 3: ENTERPRISE VALUE → EQUITY VALUE → SHARE PRICE
A21: Enterprise Value (EV = PV FCFF + PV TV) | C21: =C10+C17 -> 457599.86
A22: (–) Total Debt (₹ Cr) | C22: ='Historical Financials'!H38 -> 3741
A23: (+) Cash & Investments (₹ Cr) | C23: ='Historical Financials'!H28 -> 15450
A24: Equity Value (₹ Cr) | C24: =C21-C22+C23 -> 469308.86
A25: Shares Outstanding (Cr) | C25: 414
A26: Intrinsic Value per Share (₹) | C26: =(C24*100)/C25 -> 113359.63
A27: Current Market Price (₹) | C27: 1484
A28: Upside / (Downside) % | C28: =(C26-C27)/C27 -> 75.38789
A29: Investment Recommendation | C29: =IF(C26>C27*1.15,"BUY ▲",IF(C26<C27*0.85,"SELL ▼","HOLD ◆")) -> BUY ▲

Sheet Sensitivity Analysis
A1: SENSITIVITY ANALYSIS — WACC vs Terminal Growth Rate
A2: This matrix shows Intrinsic Value per Share (₹) for each combination of WACC (rows) and Terminal Growth Rate (cols). Yellow = within 15% of CMP | Green = Upside > 15% | Red = Downside > 15% | CMP = ₹1,484
A4: INTRINSIC VALUE PER SHARE (₹) — WACC vs TGR
A5: WACC \ TGR → | B5: 0.04 | C5: 0.045 | D5: 0.05 | E5: 0.055 | F5: 0.06 | G5: 0.065 | H5: 0.07
A6: 0.105 | B6: =('Forecast Model'!D16/(1+0.105)^1+'Forecast Model'!E16/(1+0.105)^2+'Forecast Model'!F16/(1+0.105)^3+'Forecast Model'!G16/(1+0.105)^4+'Forecast Model'!H16/(1+0.105)^5+('Forecast Model'!H16*(1+0.04))/(0.105-0.04)/(1+0.105)^5-'DCF Valuation'!C22+'DCF Valuation'!C23)*100/'DCF Valuation'!C25 -> 149738.39 | C6: =('Forecast Model'!D16/(1+0.105)^1+'Forecast Model'!E16/(1+0.105)^2+'Forecast Model'!F16/(1+0.105)^3+'Forecast Model'!G16/(1+0.105)^4+'Forecast Model'!H16/(1+0.105)^5+('Forecast Model'!H16*(1+0.045))/(0.105-0.045)/(1+0.105)^5-'DCF Valuation'!C22+'DCF Valuation'!C23)*100/'DCF Valuation'!C25 -> 159605.09 | D6: =('Forecast Model'!D16/(1+0.105)^1+'Forecast Model'!E16/(1+0.105)^2+'Forecast Model'!F16/(1+0.105)^3+'Forecast Model'!G16/(1+0.105)^4+'Forecast Model'!H16/(1+0.105)^5+('Forecast Model'!H16*(1+0.05))/(0.105-0.05)/(1+0.105)^5-'DCF Valuation'!C22+'DCF Valuation'!C23)*100/'DCF Valuation'!C25 -> 171265.75 | E6: =('Forecast Model'!D16/(1+0.105)^1+'Forecast Model'!E16/(1+0.105)^2+'Forecast Model'!F16/(1+0.105)^3+'Forecast Model'!G16/(1+0.105)^4+'Forecast Model'!H16/(1+0.105)^5+('Forecast Model'!H16*(1+0.055))/(0.105-0.055)/(1+0.105)^5-'DCF Valuation'!C22+'DCF Valuation'!C23)*100/'DCF Valuation'!C25 -> 185258.53 | F6: =('Forecast Model'!D16/(1+0.105)^1+'Forecast Model'!E16/(1+0.105)^2+'Forecast Model'!F16/(1+0.105)^3+'Forecast Model'!G16/(1+0.105)^4+'Forecast Model'!H16/(1+0.105)^5+('Forecast Model'!H16*(1+0.06))/(0.105-0.06)/(1+0.105)^5-'DCF Valuation'!C22+'DCF Valuation'!C23)*100/'DCF Valuation'!C25 -> 202360.83 | G6: =('Forecast Model'!D16/(1+0.105)^1+'Forecast Model'!E16/(1+0.105)^2+'Forecast Model'!F16/(1+0.105)^3+'Forecast Model'!G16/(1+0.105)^4+'Forecast Model'!H16/(1+0.105)^5+('Forecast Model'!H16*(1+0.065))/(0.105-0.065)/(1+0.105)^5-'DCF Valuation'!C22+'DCF Valuation'!C23)*100/'DCF Valuation'!C25 -> 223738.69 | H6: =('Forecast Model'!D16/(1+0.105)^1+'Forecast Model'!E16/(1+0.105)^2+'Forecast Model'!F16/(1+0.105)^3+'Forecast Model'!G16/(1+0.105)^4+'Forecast Model'!H16/(1+0.105)^5+('Forecast Model'!H16*(1+0.07))/(0.105-0.07)/(1+0.105)^5-'DCF Valuation'!C22+'DCF Valuation'!C23)*100/'DCF Valuation'!C25 -> 251224.52
A7: 0.11 | B7: =('Forecast Model'!D16/(1+0.11)^1+'Forecast Model'!E16/(1+0.11)^2+'Forecast Model'!F16/(1+0.11)^3+'Forecast Model'!G16/(1+0.11)^4+'Forecast Model'!H16/(1+0.11)^5+('Forecast Model'!H16*(1+0.04))/(0.11-0.04)/(1+0.11)^5-'DCF Valuation'!C22+'DCF Valuation'!C23)*100/'DCF Valuation'!C25 -> 138997.32 | C7: =('Forecast Model'!D16/(1+0.11)^1+'Forecast Model'!E16/(1+0.11)^2+'Forecast Model'!F16/(1+0.11)^3+'Forecast Model'!G16/(1+0.11)^4+'Forecast Model'!H16/(1+0.11)^5+('Forecast Model'!H16*(1+0.045))/(0.11-0.045)/(1+0.11)^5-'DCF Valuation'!C22+'DCF Valuation'!C23)*100/'DCF Valuation'!C25 -> 147303.14 | D7: =('Forecast Model'!D16/(1+0.11)^1+'Forecast Model'!E16/(1+0.11)^2+'Forecast Model'!F16/(1+0.11)^3+'Forecast Model'!G16/(1+0.11)^4+'Forecast Model'!H16/(1+0.11)^5+('Forecast Model'!H16*(1+0.05))/(0.11-0.05)/(1+0.11)^5-'DCF Valuation'!C22+'DCF Valuation'!C23)*100/'DCF Valuation'!C25 -> 156993.27 | E7: =('Forecast Model'!D16/(1+0.11)^1+'Forecast Model'!E16/(1+0.11)^2+'Forecast Model'!F16/(1+0.11)^3+'Forecast Model'!G16/(1+0.11)^4+'Forecast Model'!H16/(1+0.11)^5+('Forecast Model'!H16*(1+0.055))/(0.11-0.055)/(1+0.11)^5-'DCF Valuation'!C22+'DCF Valuation'!C23)*100/'DCF Valuation'!C25 -> 168445.23 | F7: =('Forecast Model'!D16/(1+0.11)^1+'Forecast Model'!E16/(1+0.11)^2+'Forecast Model'!F16/(1+0.11)^3+'Forecast Model'!G16/(1+0.11)^4+'Forecast Model'!H16/(1+0.11)^5+('Forecast Model'!H16*(1+0.06))/(0.11-0.06)/(1+0.11)^5-'DCF Valuation'!C22+'DCF Valuation'!C23)*100/'DCF Valuation'!C25 -> 182187.6 | G7: =('Forecast Model'!D16/(1+0.11)^1+'Forecast Model'!E16/(1+0.11)^2+'Forecast Model'!F16/(1+0.11)^3+'Forecast Model'!G16/(1+0.11)^4+'Forecast Model'!H16/(1+0.11)^5+('Forecast Model'!H16*(1+0.065))/(0.11-0.065)/(1+0.11)^5-'DCF Valuation'!C22+'DCF Valuation'!C23)*100/'DCF Valuation'!C25 -> 198983.82 | H7: =('Forecast Model'!D16/(1+0.11)^1+'Forecast Model'!E16/(1+0.11)^2+'Forecast Model'!F16/(1+0.11)^3+'Forecast Model'!G16/(1+0.11)^4+'Forecast Model'!H16/(1+0.11)^5+('Forecast Model'!H16*(1+0.07))/(0.11-0.07)/(1+0.11)^5-'DCF Valuation'!C22+'DCF Valuation'!C23)*100/'DCF Valuation'!C25 -> 219979.09
A8: 0.115 | B8: =('Forecast Model'!D16/(1+0.115)^1+'Forecast Model'!E16/(1+0.115)^2+'Forecast Model'!F16/(1+0.115)^3+'Forecast Model'!G16/(1+0.115)^4+'Forecast Model'!H16/(1+0.115)^5+('Forecast Model'!H16*(1+0.04))/(0.115-0.04)/(1+0.115)^5-'DCF Valuation'!C22+'DCF Valuation'!C23)*100/'DCF Valuation'!C25 -> 129692.74 | C8: =('Forecast Model'!D16/(1+0.115)^1+'Forecast Model'!E16/(1+0.115)^2+'Forecast Model'!F16/(1+0.115)^3+'Forecast Model'!G16/(1+0.115)^4+'Forecast Model'!H16/(1+0.115)^5+('Forecast Model'!H16*(1+0.045))/(0.115-0.045)/(1+0.115)^5-'DCF Valuation'!C22+'DCF Valuation'!C23)*100/'DCF Valuation'!C25 -> 136762.86 | D8: =('Forecast Model'!D16/(1+0.115)^1+'Forecast Model'!E16/(1+0.115)^2+'Forecast Model'!F16/(1+0.115)^3+'Forecast Model'!G16/(1+0.115)^4+'Forecast Model'!H16/(1+0.115)^5+('Forecast Model'!H16*(1+0.05))/(0.115-0.05)/(1+0.115)^5-'DCF Valuation'!C22+'DCF Valuation'!C23)*100/'DCF Valuation'!C25 -> 144920.7 | E8: =('Forecast Model'!D16/(1+0.115)^1+'Forecast Model'!E16/(1+0.115)^2+'Forecast Model'!F16/(1+0.115)^3+'Forecast Model'!G16/(1+0.115)^4+'Forecast Model'!H16/(1+0.115)^5+('Forecast Model'!H16*(1+0.055))/(0.115-0.055)/(1+0.115)^5-'DCF Valuation'!C22+'DCF Valuation'!C23)*100/'DCF Valuation'!C25 -> 154438.18 | F8: =('Forecast Model'!D16/(1+0.115)^1+'Forecast Model'!E16/(1+0.115)^2+'Forecast Model'!F16/(1+0.115)^3+'Forecast Model'!G16/(1+0.115)^4+'Forecast Model'!H16/(1+0.115)^5+('Forecast Model'!H16*(1+0.06))/(0.115-0.06)/(1+0.115)^5-'DCF Valuation'!C22+'DCF Valuation'!C23)*100/'DCF Valuation'!C25 -> 165686.11 | G8: =('Forecast Model'!D16/(1+0.115)^1+'Forecast Model'!E16/(1+0.115)^2+'Forecast Model'!F16/(1+0.115)^3+'Forecast Model'!G16/(1+0.115)^4+'Forecast Model'!H16/(1+0.115)^5+('Forecast Model'!H16*(1+0.065))/(0.115-0.065)/(1+0.115)^5-'DCF Valuation'!C22+'DCF Valuation'!C23)*100/'DCF Valuation'!C25 -> 179183.63 | H8: =('Forecast Model'!D16/(1+0.115)^1+'Forecast Model'!E16/(1+0.115)^2+'Forecast Model'!F16/(1+0.115)^3+'Forecast Model'!G16/(1+0.115)^4+'Forecast Model'!H16/(1+0.115)^5+('Forecast Model'!H16*(1+0.07))/(0.115-0.07)/(1+0.115)^5-'DCF Valuation'!C22+'DCF Valuation'!C23)*100/'DCF Valuation'!C25 -> 195680.59
A9: 0.12 | B9: =('Forecast Model'!D16/(1+0.12)^1+'Forecast Model'!E16/(1+0.12)^2+'Forecast Model'!F16/(1+0.12)^3+'Forecast Model'!G16/(1+0.12)^4+'Forecast Model'!H16/(1+0.12)^5+('Forecast Model'!H16*(1+0.04))/(0.12-0.04)/(1+0.12)^5-'DCF Valuation'!C22+'DCF Valuation'!C23)*100/'DCF Valuation'!C25 -> 121555.21 | C9: =('Forecast Model'!D16/(1+0.12)^1+'Forecast Model'!E16/(1+0.12)^2+'Forecast Model'!F16/(1+0.12)^3+'Forecast Model'!G16/(1+0.12)^4+'Forecast Model'!H16/(1+0.12)^5+('Forecast Model'!H16*(1+0.045))/(0.12-0.045)/(1+0.12)^5-'DCF Valuation'!C22+'DCF Valuation'!C23)*100/'DCF Valuation'!C25 -> 127631.84 | D9: =('Forecast Model'!D16/(1+0.12)^1+'Forecast Model'!E16/(1+0.12)^2+'Forecast Model'!F16/(1+0.12)^3+'Forecast Model'!G16/(1+0.12)^4+'Forecast Model'!H16/(1+0.12)^5+('Forecast Model'!H16*(1+0.05))/(0.12-0.05)/(1+0.12)^5-'DCF Valuation'!C22+'DCF Valuation'!C23)*100/'DCF Valuation'!C25 -> 134576.56 | E9: =('Forecast Model'!D16/(1+0.12)^1+'Forecast Model'!E16/(1+0.12)^2+'Forecast Model'!F16/(1+0.12)^3+'Forecast Model'!G16/(1+0.12)^4+'Forecast Model'!H16/(1+0.12)^5+('Forecast Model'!H16*(1+0.055))/(0.12-0.055)/(1+0.12)^5-'DCF Valuation'!C22+'DCF Valuation'!C23)*100/'DCF Valuation'!C25 -> 142589.69 | F9: =('Forecast Model'!D16/(1+0.12)^1+'Forecast Model'!E16/(1+0.12)^2+'Forecast Model'!F16/(1+0.12)^3+'Forecast Model'!G16/(1+0.12)^4+'Forecast Model'!H16/(1+0.12)^5+('Forecast Model'!H16*(1+0.06))/(0.12-0.06)/(1+0.12)^5-'DCF Valuation'!C22+'DCF Valuation'!C23)*100/'DCF Valuation'!C25 -> 151938.35 | G9: =('Forecast Model'!D16/(1+0.12)^1+'Forecast Model'!E16/(1+0.12)^2+'Forecast Model'!F16/(1+0.12)^3+'Forecast Model'!G16/(1+0.12)^4+'Forecast Model'!H16/(1+0.12)^5+('Forecast Model'!H16*(1+0.065))/(0.12-0.065)/(1+0.12)^5-'DCF Valuation'!C22+'DCF Valuation'!C23)*100/'DCF Valuation'!C25 -> 162986.77 | H9: =('Forecast Model'!D16/(1+0.12)^1+'Forecast Model'!E16/(1+0.12)^2+'Forecast Model'!F16/(1+0.12)^3+'Forecast Model'!G16/(1+0.12)^4+'Forecast Model'!H16/(1+0.12)^5+('Forecast Model'!H16*(1+0.07))/(0.12-0.07)/(1+0.12)^5-'DCF Valuation'!C22+'DCF Valuation'!C23)*100/'DCF Valuation'!C25 -> 176244.86
A10: 0.125 | B10: =('Forecast Model'!D16/(1+0.125)^1+'Forecast Model'!E16/(1+0.125)^2+'Forecast Model'!F16/(1+0.125)^3+'Forecast Model'!G16/(1+0.125)^4+'Forecast Model'!H16/(1+0.125)^5+('Forecast Model'!H16*(1+0.04))/(0.125-0.04)/(1+0.125)^5-'DCF Valuation'!C22+'DCF Valuation'!C23)*100/'DCF Valuation'!C25 -> 114378.7 | C10: =('Forecast Model'!D16/(1+0.125)^1+'Forecast Model'!E16/(1+0.125)^2+'Forecast Model'!F16/(1+0.125)^3+'Forecast Model'!G16/(1+0.125)^4+'Forecast Model'!H16/(1+0.125)^5+('Forecast Model'!H16*(1+0.045))/(0.125-0.045)/(1+0.125)^5-'DCF Valuation'!C22+'DCF Valuation'!C23)*100/'DCF Valuation'!C25 -> 119645.74 | D10: =('Forecast Model'!D16/(1+0.125)^1+'Forecast Model'!E16/(1+0.125)^2+'Forecast Model'!F16/(1+0.125)^3+'Forecast Model'!G16/(1+0.125)^4+'Forecast Model'!H16/(1+0.125)^5+('Forecast Model'!H16*(1+0.05))/(0.125-0.05)/(1+0.125)^5-'DCF Valuation'!C22+'DCF Valuation'!C23)*100/'DCF Valuation'!C25 -> 125615.06 | E10: =('Forecast Model'!D16/(1+0.125)^1+'Forecast Model'!E16/(1+0.125)^2+'Forecast Model'!F16/(1+0.125)^3+'Forecast Model'!G16/(1+0.125)^4+'Forecast Model'!H16/(1+0.125)^5+('Forecast Model'!H16*(1+0.055))/(0.125-0.055)/(1+0.125)^5-'DCF Valuation'!C22+'DCF Valuation'!C23)*100/'DCF Valuation'!C25 -> 132437.14 | F10: =('Forecast Model'!D16/(1+0.125)^1+'Forecast Model'!E16/(1+0.125)^2+'Forecast Model'!F16/(1+0.125)^3+'Forecast Model'!G16/(1+0.125)^4+'Forecast Model'!H16/(1+0.125)^5+('Forecast Model'!H16*(1+0.06))/(0.125-0.06)/(1+0.125)^5-'DCF Valuation'!C22+'DCF Valuation'!C23)*100/'DCF Valuation'!C25 -> 140308.76 | G10: =('Forecast Model'!D16/(1+0.125)^1+'Forecast Model'!E16/(1+0.125)^2+'Forecast Model'!F16/(1+0.125)^3+'Forecast Model'!G16/(1+0.125)^4+'Forecast Model'!H16/(1+0.125)^5+('Forecast Model'!H16*(1+0.065))/(0.125-0.065)/(1+0.125)^5-'DCF Valuation'!C22+'DCF Valuation'!C23)*100/'DCF Valuation'!C25 -> 149492.33 | H10: =('Forecast Model'!D16/(1+0.125)^1+'Forecast Model'!E16/(1+0.125)^2+'Forecast Model'!F16/(1+0.125)^3+'Forecast Model'!G16/(1+0.125)^4+'Forecast Model'!H16/(1+0.125)^5+('Forecast Model'!H16*(1+0.07))/(0.125-0.07)/(1+0.125)^5-'DCF Valuation'!C22+'DCF Valuation'!C23)*100/'DCF Valuation'!C25 -> 160345.63
A11: 0.13 | B11: =('Forecast Model'!D16/(1+0.13)^1+'Forecast Model'!E16/(1+0.13)^2+'Forecast Model'!F16/(1+0.13)^3+'Forecast Model'!G16/(1+0.13)^4+'Forecast Model'!H16/(1+0.13)^5+('Forecast Model'!H16*(1+0.04))/(0.13-0.04)/(1+0.13)^5-'DCF Valuation'!C22+'DCF Valuation'!C23)*100/'DCF Valuation'!C25 -> 108002.95 | C11: =('Forecast Model'!D16/(1+0.13)^1+'Forecast Model'!E16/(1+0.13)^2+'Forecast Model'!F16/(1+0.13)^3+'Forecast Model'!G16/(1+0.13)^4+'Forecast Model'!H16/(1+0.13)^5+('Forecast Model'!H16*(1+0.045))/(0.13-0.045)/(1+0.13)^5-'DCF Valuation'!C22+'DCF Valuation'!C23)*100/'DCF Valuation'!C25 -> 112602.45 | D11: =('Forecast Model'!D16/(1+0.13)^1+'Forecast Model'!E16/(1+0.13)^2+'Forecast Model'!F16/(1+0.13)^3+'Forecast Model'!G16/(1+0.13)^4+'Forecast Model'!H16/(1+0.13)^5+('Forecast Model'!H16*(1+0.05))/(0.13-0.05)/(1+0.13)^5-'DCF Valuation'!C22+'DCF Valuation'!C23)*100/'DCF Valuation'!C25 -> 117776.89 | E11: =('Forecast Model'!D16/(1+0.13)^1+'Forecast Model'!E16/(1+0.13)^2+'Forecast Model'!F16/(1+0.13)^3+'Forecast Model'!G16/(1+0.13)^4+'Forecast Model'!H16/(1+0.13)^5+('Forecast Model'!H16*(1+0.055))/(0.13-0.055)/(1+0.13)^5-'DCF Valuation'!C22+'DCF Valuation'!C23)*100/'DCF Valuation'!C25 -> 123641.25 | F11: =('Forecast Model'!D16/(1+0.13)^1+'Forecast Model'!E16/(1+0.13)^2+'Forecast Model'!F16/(1+0.13)^3+'Forecast Model'!G16/(1+0.13)^4+'Forecast Model'!H16/(1+0.13)^5+('Forecast Model'!H16*(1+0.06))/(0.13-0.06)/(1+0.13)^5-'DCF Valuation'!C22+'DCF Valuation'!C23)*100/'DCF Valuation'!C25 -> 130343.39 | G11: =('Forecast Model'!D16/(1+0.13)^1+'Forecast Model'!E16/(1+0.13)^2+'Forecast Model'!F16/(1+0.13)^3+'Forecast Model'!G16/(1+0.13)^4+'Forecast Model'!H16/(1+0.13)^5+('Forecast Model'!H16*(1+0.065))/(0.13-0.065)/(1+0.13)^5-'DCF Valuation'!C22+'DCF Valuation'!C23)*100/'DCF Valuation'!C25 -> 138076.61 | H11: =('Forecast Model'!D16/(1+0.13)^1+'Forecast Model'!E16/(1+0.13)^2+'Forecast Model'!F16/(1+0.13)^3+'Forecast Model'!G16/(1+0.13)^4+'Forecast Model'!H16/(1+0.13)^5+('Forecast Model'!H16*(1+0.07))/(0.13-0.07)/(1+0.13)^5-'DCF Valuation'!C22+'DCF Valuation'!C23)*100/'DCF Valuation'!C25 -> 147098.71
A12: 0.135 | B12: =('Forecast Model'!D16/(1+0.135)^1+'Forecast Model'!E16/(1+0.135)^2+'Forecast Model'!F16/(1+0.135)^3+'Forecast Model'!G16/(1+0.135)^4+'Forecast Model'!H16/(1+0.135)^5+('Forecast Model'!H16*(1+0.04))/(0.135-0.04)/(1+0.135)^5-'DCF Valuation'!C22+'DCF Valuation'!C23)*100/'DCF Valuation'!C25 -> 102301.45 | C12: =('Forecast Model'!D16/(1+0.135)^1+'Forecast Model'!E16/(1+0.135)^2+'Forecast Model'!F16/(1+0.135)^3+'Forecast Model'!G16/(1+0.135)^4+'Forecast Model'!H16/(1+0.135)^5+('Forecast Model'!H16*(1+0.045))/(0.135-0.045)/(1+0.135)^5-'DCF Valuation'!C22+'DCF Valuation'!C23)*100/'DCF Valuation'!C25 -> 106344.75 | D12: =('Forecast Model'!D16/(1+0.135)^1+'Forecast Model'!E16/(1+0.135)^2+'Forecast Model'!F16/(1+0.135)^3+'Forecast Model'!G16/(1+0.135)^4+'Forecast Model'!H16/(1+0.135)^5+('Forecast Model'!H16*(1+0.05))/(0.135-0.05)/(1+0.135)^5-'DCF Valuation'!C22+'DCF Valuation'!C23)*100/'DCF Valuation'!C25 -> 110863.74 | E12: =('Forecast Model'!D16/(1+0.135)^1+'Forecast Model'!E16/(1+0.135)^2+'Forecast Model'!F16/(1+0.135)^3+'Forecast Model'!G16/(1+0.135)^4+'Forecast Model'!H16/(1+0.135)^5+('Forecast Model'!H16*(1+0.055))/(0.135-0.055)/(1+0.135)^5-'DCF Valuation'!C22+'DCF Valuation'!C23)*100/'DCF Valuation'!C25 -> 115947.6 | F12: =('Forecast Model'!D16/(1+0.135)^1+'Forecast Model'!E16/(1+0.135)^2+'Forecast Model'!F16/(1+0.135)^3+'Forecast Model'!G16/(1+0.135)^4+'Forecast Model'!H16/(1+0.135)^5+('Forecast Model'!H16*(1+0.06))/(0.135-0.06)/(1+0.135)^5-'DCF Valuation'!C22+'DCF Valuation'!C23)*100/'DCF Valuation'!C25 -> 121709.31 | G12: =('Forecast Model'!D16/(1+0.135)^1+'Forecast Model'!E16/(1+0.135)^2+'Forecast Model'!F16/(1+0.135)^3+'Forecast Model'!G16/(1+0.135)^4+'Forecast Model'!H16/(1+0.135)^5+('Forecast Model'!H16*(1+0.065))/(0.135-0.065)/(1+0.135)^5-'DCF Valuation'!C22+'DCF Valuation'!C23)*100/'DCF Valuation'!C25 -> 128294.12 | H12: =('Forecast Model'!D16/(1+0.135)^1+'Forecast Model'!E16/(1+0.135)^2+'Forecast Model'!F16/(1+0.135)^3+'Forecast Model'!G16/(1+0.135)^4+'Forecast Model'!H16/(1+0.135)^5+('Forecast Model'!H16*(1+0.07))/(0.135-0.07)/(1+0.135)^5-'DCF Valuation'!C22+'DCF Valuation'!C23)*100/'DCF Valuation'!C25 -> 135891.98
A15: UPSIDE / (DOWNSIDE) vs CMP ₹1,484 — WACC vs TGR
A16: WACC \ TGR → | B16: 0.04 | C16: 0.045 | D16: 0.05 | E16: 0.055 | F16: 0.06 | G16: 0.065 | H16: 0.07
A17: 0.105 | B17: =(B6-1484)/1484 -> 99.901877 | C17: =(C6-1484)/1484 -> 106.5506 | D17: =(D6-1484)/1484 -> 114.40819 | E17: =(E6-1484)/1484 -> 123.83729 | F17: =(F6-1484)/1484 -> 135.36174 | G17: =(G6-1484)/1484 -> 149.76731 | H17: =(H6-1484)/1484 -> 168.28876
A18: 0.11 | B18: =(B7-1484)/1484 -> 92.66396 | C18: =(C7-1484)/1484 -> 98.260876 | D18: =(D7-1484)/1484 -> 104.79061 | E18: =(E7-1484)/1484 -> 112.50757 | F18: =(F7-1484)/1484 -> 121.76792 | G18: =(G7-1484)/1484 -> 133.08613 | H18: =(H7-1484)/1484 -> 147.23389
A19: 0.115 | B19: =(B8-1484)/1484 -> 86.394028 | C19: =(C8-1484)/1484 -> 91.158265 | D19: =(D8-1484)/1484 -> 96.655461 | E19: =(E8-1484)/1484 -> 103.06886 | F19: =(F8-1484)/1484 -> 110.64832 | G19: =(G8-1484)/1484 -> 119.74368 | H19: =(H8-1484)/1484 -> 130.86024
A20: 0.12 | B20: =(B9-1484)/1484 -> 80.91052 | C20: =(C9-1484)/1484 -> 85.005283 | D20: =(D9-1484)/1484 -> 89.685012 | E20: =(E9-1484)/1484 -> 95.084699 | F20: =(F9-1484)/1484 -> 101.38433 | G20: =(G9-1484)/1484 -> 108.82936 | H20: =(H9-1484)/1484 -> 117.76338
A21: 0.125 | B21: =(B10-1484)/1484 -> 76.074595 | C21: =(C10-1484)/1484 -> 79.623816 | D21: =(D10-1484)/1484 -> 83.646267 | E21: =(E10-1484)/1484 -> 88.243354 | F21: =(F10-1484)/1484 -> 93.547685 | G21: =(G10-1484)/1484 -> 99.73607 | H21: =(H10-1484)/1484 -> 107.04962
A22: 0.13 | B22: =(B11-1484)/1484 -> 71.778267 | C22: =(C11-1484)/1484 -> 74.877662 | D22: =(D11-1484)/1484 -> 78.364481 | E22: =(E11-1484)/1484 -> 82.316209 | F22: =(F11-1484)/1484 -> 86.83247 | G22: =(G11-1484)/1484 -> 92.04354 | H22: =(H11-1484)/1484 -> 98.123122
A23: 0.135 | B23: =(B12-1484)/1484 -> 67.936287 | C23: =(C12-1484)/1484 -> 70.660886 | D23: =(D12-1484)/1484 -> 73.706025 | E23: =(E12-1484)/1484 -> 77.131807 | F23: =(F12-1484)/1484 -> 81.01436 | G23: =(G12-1484)/1484 -> 85.451563 | H23: =(H12-1484)/1484 -> 90.571413

Sheet Dashboard
A1: INFOSYS LIMITED — VALUATION DASHBOARD
A3: Enterprise Value | C3: Equity Value | E3: Intrinsic Price | G3: CMP (Mkt Price) | I3: Recommendation | K3: WACC
A4: ='DCF Valuation'!C21 -> 457599.86 | C4: ='DCF Valuation'!C24 -> 469308.86 | E4: ='DCF Valuation'!C26 -> 113359.63 | G4: 1484 | I4: ='DCF Valuation'!C29 -> BUY ▲ | K4: =Assumptions!C28 -> 0.13683565
A7: ₹ Crores | C7: ₹ Crores | E7: ₹ / Share | G7: ₹ / Share | I7: Signal | K7: Discount Rate
A9: KEY METRICS SUMMARY
A10: Metric | C10: FY2022 | E10: FY2023 | G10: FY2024 | I10: FY2025 | K10: FY2026 | M10: FY2031E
A11: Revenue (₹ Cr) | C11: 121641 | E11: 146767 | G11: 153670 | I11: 165809 | K11: 180143 | M11: ='Forecast Model'!H6 -> 277143.17
A12: EBIT Margin % | C12: 0.203 | E12: 0.194 | G12: 0.194 | I12: 0.198 | K12: 0.204 | M12: ='Forecast Model'!H9 -> 0.238
A13: FCFF (₹ Cr) | C13: N/A | E13: N/A | G13: N/A | I13: N/A | K13: N/A | M13: ='Forecast Model'!H16 -> 47502.484
A15: Model Legend: Blue Text = Hardcoded Input | Black = Formula | Green = Cross-Sheet Link | Light Blue Fill = Key Assumption Cell | This dashboard auto-updates when assumptions change.
